Workbook

Sheet 指标汇总
A1: 指标 | B1: Excel公式结果 | C1: JSON记录/独立复算 | D1: 差值 | E1: 口径
A2: 架次数N | B2: =COUNTA('Q2_运输架次'!A2:A26) -> 25 | C2: 25 | D2: =B2-C2 -> 0 | E2: 仅此最终方案的运输架次
A3: 运输总能耗 kWh | B3: =SUM('Q2_运输架次'!H2:H26) -> 71.319092 | C3: 71.319092 | D3: =B3-C3 -> 0 | E3: 统一题设与补充能耗假设；不解释为实飞测量
A4: 最晚返场 s | B4: =MAX('Q2_运输架次'!G2:G26) -> 6672.0143 | C4: 6672.0143 | D4: =B4-C4 -> 0 | E4: 全部运输机完成最后任务并返回O01；不含最终充电
A5: 加权平均迟到 s | B5: =SUM('核验_逐箱'!N2:N81)/SUM('核验_逐箱'!M2:M81) -> 0 | C5: 0 | D5: =B5-C5 -> 0 | E5: 仅无硬时限箱；分母为软箱应急优先系数和
A6: 交付货箱数 | B6: =COUNTA('Q2_逐箱交付'!A2:A81) -> 80 | C6: 80 | D6: =B6-C6 -> 0 | E6: 货箱编号唯一性另由导出检查确认
A7: 硬时限箱数 | B7: =IF('核验_逐箱'!G2,1,0)+IF('核验_逐箱'!G3,1,0)+IF('核验_逐箱'!G4,1,0)+IF('核验_逐箱'!G5,1,0)+IF('核验_逐箱'!G6,1,0)+IF('核验_逐箱'!G7,1,0)+IF('核验_逐箱'!G8,1,0)+IF('核验_逐箱'!G9,1,0)+IF('核验_逐箱'!G10,1,0)+IF('核验_逐箱'!G11,1,0)+IF('核验_逐箱'!G12,1,0)+IF('核验_逐箱'!G13,1,0)+IF('核验_逐箱'!G14,1,0)+IF('核验_逐箱'!G15,1,0)+IF('核验_逐箱'!G16,1,0)+IF('核验_逐箱'!G17,1,0)+IF('核验_逐箱'!G18,1,0)+IF('核验_逐箱'!G19,1,0)+IF('核验_逐箱'!G20,1,0)+IF('核验_逐箱'!G21,1,0)+IF('核验_逐箱'!G22,1,0)+IF('核验_逐箱'!G23,1,0)+IF('核验_逐箱'!G24,1,0)+IF('核验_逐箱'!G25,1,0)+IF('核验_逐箱'!G26,1,0)+IF('核验_逐箱'!G27,1,0)+IF('核验_逐箱'!G28,1,0)+IF('核验_逐箱'!G29,1,0)+IF('核验_逐箱'!G30,1,0)+IF('核验_逐箱'!G31,1,0)+IF('核验_逐箱'!G32,1,0)+IF('核验_逐箱'!G33,1,0)+IF('核验_逐箱'!G34,1,0)+IF('核验_逐箱'!G35,1,0)+IF('核验_逐箱'!G36,1,0)+IF('核验_逐箱'!G37,1,0)+IF('核验_逐箱'!G38,1,0)+IF('核验_逐箱'!G39,1,0)+IF('核验_逐箱'!G40,1,0)+IF('核验_逐箱'!G41,1,0)+IF('核验_逐箱'!G42,1,0)+IF('核验_逐箱'!G43,1,0)+IF('核验_逐箱'!G44,1,0)+IF('核验_逐箱'!G45,1,0)+IF('核验_逐箱'!G46,1,0)+IF('核验_逐箱'!G47,1,0)+IF('核验_逐箱'!G48,1,0)+IF('核验_逐箱'!G49,1,0)+IF('核验_逐箱'!G50,1,0)+IF('核验_逐箱'!G51,1,0)+IF('核验_逐箱'!G52,1,0)+IF('核验_逐箱'!G53,1,0)+IF('核验_逐箱'!G54,1,0)+IF('核验_逐箱'!G55,1,0)+IF('核验_逐箱'!G56,1,0)+IF('核验_逐箱'!G57,1,0)+IF('核验_逐箱'!G58,1,0)+IF('核验_逐箱'!G59,1,0)+IF('核验_逐箱'!G60,1,0)+IF('核验_逐箱'!G61,1,0)+IF('核验_逐箱'!G62,1,0)+IF('核验_逐箱'!G63,1,0)+IF('核验_逐箱'!G64,1,0)+IF('核验_逐箱'!G65,1,0)+IF('核验_逐箱'!G66,1,0)+IF('核验_逐箱'!G67,1,0)+IF('核验_逐箱'!G68,1,0)+IF('核验_逐箱'!G69,1,0)+IF('核验_逐箱'!G70,1,0)+IF('核验_逐箱'!G71,1,0)+IF('核验_逐箱'!G72,1,0)+IF('核验_逐箱'!G73,1,0)+IF('核验_逐箱'!G74,1,0)+IF('核验_逐箱'!G75,1,0)+IF('核验_逐箱'!G76,1,0)+IF('核验_逐箱'!G77,1,0)+IF('核验_逐箱'!G78,1,0)+IF('核验_逐箱'!G79,1,0)+IF('核验_逐箱'!G80,1,0)+IF('核验_逐箱'!G81,1,0) -> 31 | C7: 31 | D7: =B7-C7 -> 0 | E7: 医疗或首批的并集
A8: 软时限箱数 | B8: =B6-B7 -> 49 | C8: 49 | D8: =B8-C8 -> 0 | E8: 无硬时限箱
A9: 软箱优先系数和 | B9: =SUM('核验_逐箱'!M2:M81) -> 460 | C9: 460 | D9: =B9-C9 -> 0 | E9: 当前加权迟到分母
A10: 非医疗优先系数和 | B10: =SUM('核验_逐箱'!O2:O81) -> 618 | C10: 618 | D10: =B10-C10 -> 0 | E10: 用于辨认64非医疗箱与49软箱两种口径
A11: 档案方案数 | B11: 11 | C11: 11 | D11: =B11-C11 -> 0 | E11: 独立档案页；不混入提交架次表
A12: 最终档案编号 | B12: PF0001 | E12: 按完整架次、资源与开始时刻匹配
A13: 遗憾下界 | B13: 0.058596416 | E13: 原JSON记录；范围见求解说明
A14: 遗憾上界 | B14: 0.39596236 | E14: 原JSON记录；不代表原题全局稳健最优认证

Sheet Q2_运输架次
A1: 架次编号 | B1: 无人机编号 | C1: 机型编号 | D1: 电池编号 | E1: 开始时刻（s） | F1: 访问服务区顺序 | G1: 返回O01时刻（s） | H1: 架次能耗（kWh）
A2: Q2-0001 | B2: U02 | C2: A | D2: A-BAT-04 | E2: 0 | F2: O01→S009→S002→O01 | G2: 2215.8496 | H2: 3.0155183
A3: Q2-0002 | B3: U01 | C3: A | D3: A-BAT-03 | E3: 0 | F3: O01→S001→O01 | G3: 1250.907 | H3: 1.2823638
A4: Q2-0003 | B4: U03 | C4: A | D4: A-BAT-05 | E4: 0 | F4: O01→S006→O01 | G4: 1313.4766 | H4: 1.3115627
A5: Q2-0004 | B5: U06 | C5: B | D5: B-BAT-01 | E5: 0 | F5: O01→S015→O01 | G5: 1828.3276 | H5: 2.3075883
A6: Q2-0005 | B6: U05 | C6: B | D6: B-BAT-03 | E6: 0 | F6: O01→S006→O01 | G6: 1147.27 | H6: 1.0662708
A7: Q2-0006 | B7: U08 | C7: C | D7: C-BAT-01 | E7: 0 | F7: O01→S001→S007→O01 | G7: 2481.4378 | H7: 5.4648167
A8: Q2-0007 | B8: U04 | C8: A | D8: A-BAT-01 | E8: 0 | F8: O01→S001→S013→O01 | G8: 1904.187 | H8: 2.1934019
A9: Q2-0008 | B9: U07 | C9: C | D9: C-BAT-03 | E9: 0 | F9: O01→S001→O01 | G9: 1692.175 | H9: 2.9176236
A10: Q2-0009 | B10: U05 | C10: B | D10: B-BAT-04 | E10: 1147.27 | F10: O01→S010→O01 | G10: 2702.6735 | H10: 1.8232594
A11: Q2-0010 | B11: U01 | C11: A | D11: A-BAT-02 | E11: 1250.907 | F11: O01→S014→O01 | G11: 3241.3058 | H11: 2.3694261
A12: Q2-0011 | B12: U03 | C12: A | D12: A-BAT-06 | E12: 1313.4766 | F12: O01→S001→S014→O01 | G12: 3761.0393 | H12: 2.7645301
A13: Q2-0012 | B13: U07 | C13: C | D13: C-BAT-04 | E13: 1692.175 | F13: O01→S002→O01 | G13: 3866.0172 | H13: 6.2810104
... A26: Q2-0025 | B26: U03 | C26: A | D26: A-BAT-06 | E26: 5059.6813 | F26: O01→S006→O01 | G26: 6313.158 | H26: 1.2430055

Sheet Q2_逐箱交付
A1: 货箱编号 | B1: 架次编号 | C1: 服务区编号 | D1: 交付完成时刻（s）
A2: S001-FOD-01 | B2: Q2-0002 | C2: S001 | D2: 908.57681
A3: S001-FOD-02 | B3: Q2-0008 | C3: S001 | D3: 1380.2725
A4: S001-FOD-03 | B4: Q2-0008 | C4: S001 | D4: 1380.2725
A5: S001-HYG-01 | B5: Q2-0008 | C5: S001 | D5: 1380.2725
A6: S001-HYG-02 | B6: Q2-0008 | C6: S001 | D6: 1380.2725
A7: S001-MED-01 | B7: Q2-0008 | C7: S001 | D7: 1380.2725
A8: S001-MED-02 | B8: Q2-0008 | C8: S001 | D8: 1380.2725
A9: S001-WAT-01 | B9: Q2-0011 | C9: S001 | D9: 2192.0535
A10: S001-WAT-02 | B10: Q2-0007 | C10: S001 | D10: 878.57681
A11: S001-WAT-03 | B11: Q2-0002 | C11: S001 | D11: 908.57681
A12: S001-WAT-04 | B12: Q2-0008 | C12: S001 | D12: 1380.2725
A13: S001-WAT-05 | B13: Q2-0006 | C13: S001 | D13: 1068.2725
... A81: S015-WAT-01 | B81: Q2-0004 | C81: S015 | D81: 1217.6038

Sheet 核验_架次详情
A1: 架次编号 | B1: 候选编号 | C1: 货箱编号列表 | D1: 总质量kg | E1: 总体积m3 | F1: 实际起飞s | G1: 返航SOC | H1: 充满时刻s | I1: 任务总时长s | J1: 充电时长s | K1: 访问次数 | L1: 箱数
A2: Q2-0001 | B2: K234f68aea25bdd05 | C2: S002-WAT-02;S009-FOD-01 | D2: 22 | E2: 0.055 | F2: 360 | G2: 0.32988483 | H2: 3586.9993 | I2: ='Q2_运输架次'!G2-'Q2_运输架次'!E2 -> 2215.8496 | J2: =H2-'Q2_运输架次'!G2 -> 1371.1497 | K2: 2 | L2: 2
A3: Q2-0002 | B3: K49d20eb1d5870510 | C3: S001-FOD-01;S001-WAT-03 | D3: 22 | E3: 0.055 | F3: 360 | G3: 0.71503028 | H3: 2121.3676 | I3: ='Q2_运输架次'!G3-'Q2_运输架次'!E3 -> 1250.907 | J3: =H3-'Q2_运输架次'!G3 -> 870.46064 | K3: 1 | L3: 2
A4: Q2-0003 | B4: K86ecc4edaf8253e9 | C4: S006-MED-01;S006-WAT-03 | D4: 17 | E4: 0.039 | F4: 360 | G4: 0.70854161 | H4: 2192.3725 | I4: ='Q2_运输架次'!G4-'Q2_运输架次'!E4 -> 1313.4766 | J4: =H4-'Q2_运输架次'!G4 -> 878.8959 | K4: 1 | L4: 2
A5: Q2-0004 | B5: K8d90beceb5941288 | C5: S015-FOD-01;S015-MED-01;S015-WAT-01 | D5: 25 | E5: 0.067 | F5: 390 | G5: 0.42310292 | H5: 3494.9492 | I5: ='Q2_运输架次'!G5-'Q2_运输架次'!E5 -> 1828.3276 | J5: =H5-'Q2_运输架次'!G5 -> 1666.6216 | K5: 1 | L5: 3
A6: Q2-0005 | B6: Kb6a2df3d717c6adf | C6: S006-WAT-01 | D6: 14 | E6: 0.027 | F6: 330 | G6: 0.73343231 | H6: 2275.9873 | I6: ='Q2_运输架次'!G6-'Q2_运输架次'!E6 -> 1147.27 | J6: =H6-'Q2_运输架次'!G6 -> 1128.7173 | K6: 1 | L6: 1
A7: Q2-0006 | B7: Kbde928bee685a193 | C7: S001-WAT-05;S001-WAT-06;S007-FOD-01;S007-HYG-01;S007-MED-01;S007-WAT-01;S007-WAT-02 | D7: 73 | E7: 0.183 | F7: 510 | G7: 0.31689791 | H7: 4794.8256 | I7: ='Q2_运输架次'!G7-'Q2_运输架次'!E7 -> 2481.4378 | J7: =H7-'Q2_运输架次'!G7 -> 2313.3879 | K7: 2 | L7: 7
A8: Q2-0007 | B8: Kf88b6d53dec0792e | C8: S001-WAT-02;S013-FOD-01 | D8: 22 | E8: 0.055 | F8: 360 | G8: 0.51257735 | H8: 3037.8365 | I8: ='Q2_运输架次'!G8-'Q2_运输架次'!E8 -> 1904.187 | J8: =H8-'Q2_运输架次'!G8 -> 1133.6494 | K8: 2 | L8: 2
A9: Q2-0008 | B9: Kfdb93e3bdcb02802 | C9: S001-FOD-02;S001-FOD-03;S001-HYG-01;S001-HYG-02;S001-MED-01;S001-MED-02;S001-WAT-04;S001-WAT-07;S001-WAT-08 | D9: 76 | E9: 0.231 | F9: 570 | G9: 0.63529706 | H9: 3315.6981 | I9: ='Q2_运输架次'!G9-'Q2_运输架次'!E9 -> 1692.175 | J9: =H9-'Q2_运输架次'!G9 -> 1623.523 | K9: 1 | L9: 9
A10: Q2-0009 | B10: Kada50d43912b2f82 | C10: S010-FOD-01;S010-MED-01;S010-WAT-01 | D10: 25 | E10: 0.067 | F10: 1537.27 | G10: 0.54418514 | H10: 4159.4193 | I10: ='Q2_运输架次'!G10-'Q2_运输架次'!E10 -> 1555.4035 | J10: =H10-'Q2_运输架次'!G10 -> 1456.7458 | K10: 1 | L10: 3
A11: Q2-0010 | B11: Kc58793d6022a6e66 | C11: S014-FOD-01;S014-WAT-01 | D11: 22 | E11: 0.055 | F11: 1610.907 | G11: 0.47346086 | H11: 4425.8067 | I11: ='Q2_运输架次'!G11-'Q2_运输架次'!E11 -> 1990.3989 | J11: =H11-'Q2_运输架次'!G11 -> 1184.5009 | K11: 1 | L11: 2
A12: Q2-0011 | B12: K6b3a54b7674a83f9 | C12: S001-WAT-01;S014-MED-01 | D12: 17 | E12: 0.039 | F12: 1673.4766 | G12: 0.38565997 | H12: 5059.6813 | I12: ='Q2_运输架次'!G12-'Q2_运输架次'!E12 -> 2447.5627 | J12: =H12-'Q2_运输架次'!G12 -> 1298.642 | K12: 2 | L12: 2
A13: Q2-0012 | B13: Kcb2b55c84e67d87c | C13: S002-FOD-01;S002-FOD-02;S002-HYG-01;S002-MED-01;S002-WAT-01;S002-WAT-03;S002-WAT-04 | D13: 67 | E13: 0.184 | F13: 2202.175 | G13: 0.2148737 | H13: 6400.4575 | I13: ='Q2_运输架次'!G13-'Q2_运输架次'!E13 -> 2173.8422 | J13: =H13-'Q2_运输架次'!G13 -> 2534.4403 | K13: 1 | L13: 7
... A26: Q2-0025 | B26: K213f1ba15c404878 | C26: S006-HYG-01 | D26: 6 | E26: 0.035 | F26: 5389.6813 | G26: 0.72377656 | H26: 7172.2484 | I26: ='Q2_运输架次'!G26-'Q2_运输架次'!E26 -> 1253.4766 | J26: =H26-'Q2_运输架次'!G26 -> 859.09048 | K26: 1 | L26: 1

Sheet 核验_逐箱
A1: 货箱编号 | B1: 架次编号 | C1: 服务区编号 | D1: 物资类型 | E1: 交付完成时刻s | F1: 期望时刻s | G1: 硬时限 | H1: 适用截止时刻s | I1: 首批保障 | J1: 优先系数 | K1: 时限裕度s | L1: 迟到量s | M1: 软箱优先系数 | N1: 软箱加权迟到s | O1: 非医疗优先系数 | P1: 医疗标记
A2: S001-FOD-01 | B2: Q2-0002 | C2: S001 | D2: 应急食品 | E2: ='Q2_逐箱交付'!D2 -> 908.57681 | F2: 7200 | G2: FALSE | I2: FALSE | J2: 10 | K2: =IF(G2,H2-E2,"") | L2: =MAX(0,E2-F2) -> 0 | M2: =IF(G2,0,J2) -> 10 | N2: =M2*L2 -> 0 | O2: =IF(P2,0,J2) -> 10 | P2: FALSE
A3: S001-FOD-02 | B3: Q2-0008 | C3: S001 | D3: 应急食品 | E3: ='Q2_逐箱交付'!D3 -> 1380.2725 | F3: 7200 | G3: FALSE | I3: FALSE | J3: 10 | K3: =IF(G3,H3-E3,"") | L3: =MAX(0,E3-F3) -> 0 | M3: =IF(G3,0,J3) -> 10 | N3: =M3*L3 -> 0 | O3: =IF(P3,0,J3) -> 10 | P3: FALSE
A4: S001-FOD-03 | B4: Q2-0008 | C4: S001 | D4: 应急食品 | E4: ='Q2_逐箱交付'!D4 -> 1380.2725 | F4: 7200 | G4: FALSE | I4: FALSE | J4: 10 | K4: =IF(G4,H4-E4,"") | L4: =MAX(0,E4-F4) -> 0 | M4: =IF(G4,0,J4) -> 10 | N4: =M4*L4 -> 0 | O4: =IF(P4,0,J4) -> 10 | P4: FALSE
A5: S001-HYG-01 | B5: Q2-0008 | C5: S001 | D5: 生活卫生用品 | E5: ='Q2_逐箱交付'!D5 -> 1380.2725 | F5: 10800 | G5: FALSE | I5: FALSE | J5: 8 | K5: =IF(G5,H5-E5,"") | L5: =MAX(0,E5-F5) -> 0 | M5: =IF(G5,0,J5) -> 8 | N5: =M5*L5 -> 0 | O5: =IF(P5,0,J5) -> 8 | P5: FALSE
A6: S001-HYG-02 | B6: Q2-0008 | C6: S001 | D6: 生活卫生用品 | E6: ='Q2_逐箱交付'!D6 -> 1380.2725 | F6: 10800 | G6: FALSE | I6: FALSE | J6: 8 | K6: =IF(G6,H6-E6,"") | L6: =MAX(0,E6-F6) -> 0 | M6: =IF(G6,0,J6) -> 8 | N6: =M6*L6 -> 0 | O6: =IF(P6,0,J6) -> 8 | P6: FALSE
A7: S001-MED-01 | B7: Q2-0008 | C7: S001 | D7: 医疗物资 | E7: ='Q2_逐箱交付'!D7 -> 1380.2725 | F7: 3600 | G7: TRUE | H7: 3600 | I7: TRUE | J7: 24 | K7: =IF(G7,H7-E7,"") -> 2219.7275 | L7: =MAX(0,E7-F7) -> 0 | M7: =IF(G7,0,J7) -> 0 | N7: =M7*L7 -> 0 | O7: =IF(P7,0,J7) -> 0 | P7: TRUE
A8: S001-MED-02 | B8: Q2-0008 | C8: S001 | D8: 医疗物资 | E8: ='Q2_逐箱交付'!D8 -> 1380.2725 | F8: 3600 | G8: TRUE | H8: 3600 | I8: FALSE | J8: 24 | K8: =IF(G8,H8-E8,"") -> 2219.7275 | L8: =MAX(0,E8-F8) -> 0 | M8: =IF(G8,0,J8) -> 0 | N8: =M8*L8 -> 0 | O8: =IF(P8,0,J8) -> 0 | P8: TRUE
A9: S001-WAT-01 | B9: Q2-0011 | C9: S001 | D9: 饮用水 | E9: ='Q2_逐箱交付'!D9 -> 2192.0535 | F9: 3600 | G9: TRUE | H9: 3600 | I9: TRUE | J9: 12 | K9: =IF(G9,H9-E9,"") -> 1407.9465 | L9: =MAX(0,E9-F9) -> 0 | M9: =IF(G9,0,J9) -> 0 | N9: =M9*L9 -> 0 | O9: =IF(P9,0,J9) -> 12 | P9: FALSE
A10: S001-WAT-02 | B10: Q2-0007 | C10: S001 | D10: 饮用水 | E10: ='Q2_逐箱交付'!D10 -> 878.57681 | F10: 3600 | G10: FALSE | I10: FALSE | J10: 12 | K10: =IF(G10,H10-E10,"") | L10: =MAX(0,E10-F10) -> 0 | M10: =IF(G10,0,J10) -> 12 | N10: =M10*L10 -> 0 | O10: =IF(P10,0,J10) -> 12 | P10: FALSE
A11: S001-WAT-03 | B11: Q2-0002 | C11: S001 | D11: 饮用水 | E11: ='Q2_逐箱交付'!D11 -> 908.57681 | F11: 3600 | G11: FALSE | I11: FALSE | J11: 12 | K11: =IF(G11,H11-E11,"") | L11: =MAX(0,E11-F11) -> 0 | M11: =IF(G11,0,J11) -> 12 | N11: =M11*L11 -> 0 | O11: =IF(P11,0,J11) -> 12 | P11: FALSE
A12: S001-WAT-04 | B12: Q2-0008 | C12: S001 | D12: 饮用水 | E12: ='Q2_逐箱交付'!D12 -> 1380.2725 | F12: 3600 | G12: FALSE | I12: FALSE | J12: 12 | K12: =IF(G12,H12-E12,"") | L12: =MAX(0,E12-F12) -> 0 | M12: =IF(G12,0,J12) -> 12 | N12: =M12*L12 -> 0 | O12: =IF(P12,0,J12) -> 12 | P12: FALSE
A13: S001-WAT-05 | B13: Q2-0006 | C13: S001 | D13: 饮用水 | E13: ='Q2_逐箱交付'!D13 -> 1068.2725 | F13: 3600 | G13: FALSE | I13: FALSE | J13: 12 | K13: =IF(G13,H13-E13,"") | L13: =MAX(0,E13-F13) -> 0 | M13: =IF(G13,0,J13) -> 12 | N13: =M13*L13 -> 0 | O13: =IF(P13,0,J13) -> 12 | P13: FALSE
A14: S001-WAT-06 | B14: Q2-0006 | C14: S001 | D14: 饮用水 | E14: ='Q2_逐箱交付'!D14 -> 1068.2725 | F14: 3600 | G14: FALSE | I14: FALSE | J14: 12 | K14: =IF(G14,H14-E14,"") | L14: =MAX(0,E14-F14) -> 0 | M14: =IF(G14,0,J14) -> 12 | N14: =M14*L14 -> 0 | O14: =IF(P14,0,J14) -> 12 | P14: FALSE
A15: S001-WAT-07 | B15: Q2-0008 | C15: S001 | D15: 饮用水 | E15: ='Q2_逐箱交付'!D15 -> 1380.2725 | F15: 3600 | G15: FALSE | I15: FALSE | J15: 12 | K15: =IF(G15,H15-E15,"") | L15: =MAX(0,E15-F15) -> 0 | M15: =IF(G15,0,J15) -> 12 | N15: =M15*L15 -> 0 | O15: =IF(P15,0,J15) -> 12 | P15: FALSE
A16: S001-WAT-08 | B16: Q2-0008 | C16: S001 | D16: 饮用水 | E16: ='Q2_逐箱交付'!D16 -> 1380.2725 | F16: 3600 | G16: FALSE | I16: FALSE | J16: 12 | K16: =IF(G16,H16-E16,"") | L16: =MAX(0,E16-F16) -> 0 | M16: =IF(G16,0,J16) -> 12 | N16: =M16*L16 -> 0 | O16: =IF(P16,0,J16) -> 12 | P16: FALSE
A17: S002-FOD-01 | B17: Q2-0012 | C17: S002 | D17: 应急食品 | E17: ='Q2_逐箱交付'!D17 -> 3245.5061 | F17: 7200 | G17: FALSE | I17: FALSE | J17: 10 | K17: =IF(G17,H17-E17,"") | L17: =MAX(0,E17-F17) -> 0 | M17: =IF(G17,0,J17) -> 10 | N17: =M17*L17 -> 0 | O17: =IF(P17,0,J17) -> 10 | P17: FALSE
A18: S002-FOD-02 | B18: Q2-0012 | C18: S002 | D18: 应急食品 | E18: ='Q2_逐箱交付'!D18 -> 3245.5061 | F18: 7200 | G18: FALSE | I18: FALSE | J18: 10 | K18: =IF(G18,H18-E18,"") | L18: =MAX(0,E18-F18) -> 0 | M18: =IF(G18,0,J18) -> 10 | N18: =M18*L18 -> 0 | O18: =IF(P18,0,J18) -> 10 | P18: FALSE
A19: S002-HYG-01 | B19: Q2-0012 | C19: S002 | D19: 生活卫生用品 | E19: ='Q2_逐箱交付'!D19 -> 3245.5061 | F19: 10800 | G19: FALSE | I19: FALSE | J19: 8 | K19: =IF(G19,H19-E19,"") | L19: =MAX(0,E19-F19) -> 0 | M19: =IF(G19,0,J19) -> 8 | N19: =M19*L19 -> 0 | O19: =IF(P19,0,J19) -> 8 | P19: FALSE
A20: S002-MED-01 | B20: Q2-0012 | C20: S002 | D20: 医疗物资 | E20: ='Q2_逐箱交付'!D20 -> 3245.5061 | F20: 3600 | G20: TRUE | H20: 3600 | I20: TRUE | J20: 24 | K20: =IF(G20,H20-E20,"") -> 354.49387 | L20: =MAX(0,E20-F20) -> 0 | M20: =IF(G20,0,J20) -> 0 | N20: =M20*L20 -> 0 | O20: =IF(P20,0,J20) -> 0 | P20: TRUE
A21: S002-WAT-01 | B21: Q2-0012 | C21: S002 | D21: 饮用水 | E21: ='Q2_逐箱交付'!D21 -> 3245.5061 | F21: 3600 | G21: TRUE | H21: 3600 | I21: TRUE | J21: 12 | K21: =IF(G21,H21-E21,"") -> 354.49387 | L21: =MAX(0,E21-F21) -> 0 | M21: =IF(G21,0,J21) -> 0 | N21: =M21*L21 -> 0 | O21: =IF(P21,0,J21) -> 12 | P21: FALSE
A22: S002-WAT-02 | B22: Q2-0001 | C22: S002 | D22: 饮用水 | E22: ='Q2_逐箱交付'!D22 -> 1495.902 | F22: 3600 | G22: FALSE | I22: FALSE | J22: 12 | K22: =IF(G22,H22-E22,"") | L22: =MAX(0,E22-F22) -> 0 | M22: =IF(G22,0,J22) -> 12 | N22: =M22*L22 -> 0 | O22: =IF(P22,0,J22) -> 12 | P22: FALSE
A23: S002-WAT-03 | B23: Q2-0012 | C23: S002 | D23: 饮用水 | E23: ='Q2_逐箱交付'!D23 -> 3245.5061 | F23: 3600 | G23: FALSE | I23: FALSE | J23: 12 | K23: =IF(G23,H23-E23,"") | L23: =MAX(0,E23-F23) -> 0 | M23: =IF(G23,0,J23) -> 12 | N23: =M23*L23 -> 0 | O23: =IF(P23,0,J23) -> 12 | P23: FALSE
A24: S002-WAT-04 | B24: Q2-0012 | C24: S002 | D24: 饮用水 | E24: ='Q2_逐箱交付'!D24 -> 3245.5061 | F24: 3600 | G24: FALSE | I24: FALSE | J24: 12 | K24: =IF(G24,H24-E24,"") | L24: =MAX(0,E24-F24) -> 0 | M24: =IF(G24,0,J24) -> 12 | N24: =M24*L24 -> 0 | O24: =IF(P24,0,J24) -> 12 | P24: FALSE
A25: S003-FOD-01 | B25: Q2-0019 | C25: S003 | D25: 应急食品 | E25: ='Q2_逐箱交付'!D25 -> 5577.5661 | F25: 10800 | G25: FALSE | I25: FALSE | J25: 8 | K25: =IF(G25,H25-E25,"") | L25: =MAX(0,E25-F25) -> 0 | M25: =IF(G25,0,J25) -> 8 | N25: =M25*L25 -> 0 | O25: =IF(P25,0,J25) -> 8 | P25: FALSE
A26: S003-FOD-02 | B26: Q2-0019 | C26: S003 | D26: 应急食品 | E26: ='Q2_逐箱交付'!D26 -> 5577.5661 | F26: 10800 | G26: FALSE | I26: FALSE | J26: 8 | K26: =IF(G26,H26-E26,"") | L26: =MAX(0,E26-F26) -> 0 | M26: =IF(G26,0,J26) -> 8 | N26: =M26*L26 -> 0 | O26: =IF(P26,0,J26) -> 8 | P26: FALSE
A27: S003-HYG-01 | B27: Q2-0019 | C27: S003 | D27: 生活卫生用品 | E27: ='Q2_逐箱交付'!D27 -> 5577.5661 | F27: 14400 | G27: FALSE | I27: FALSE | J27: 6 | K27: =IF(G27,H27-E27,"") | L27: =MAX(0,E27-F27) -> 0 | M27: =IF(G27,0,J27) -> 6 | N27: =M27*L27 -> 0 | O27: =IF(P27,0,J27) -> 6 | P27: FALSE
A28: S003-MED-01 | B28: Q2-0019 | C28: S003 | D28: 医疗物资 | E28: ='Q2_逐箱交付'!D28 -> 5577.5661 | F28: 7200 | G28: TRUE | H28: 7200 | I28: TRUE | J28: 20 | K28: =IF(G28,H28-E28,"") -> 1622.4339 | L28: =MAX(0,E28-F28) -> 0 | M28: =IF(G28,0,J28) -> 0 | N28: =M28*L28 -> 0 | O28: =IF(P28,0,J28) -> 0 | P28: TRUE
A29: S003-WAT-01 | B29: Q2-0019 | C29: S003 | D29: 饮用水 | E29: ='Q2_逐箱交付'!D29 -> 5577.5661 | F29: 7200 | G29: TRUE | H29: 7200 | I29: TRUE | J29: 10 | K29: =IF(G29,H29-E29,"") -> 1622.4339 | L29: =MAX(0,E29-F29) -> 0 | M29: =IF(G29,0,J29) -> 0 | N29: =M29*L29 -> 0 | O29: =IF(P29,0,J29) -> 10 | P29: FALSE
A30: S003-WAT-02 | B30: Q2-0019 | C30: S003 | D30: 饮用水 | E30: ='Q2_逐箱交付'!D30 -> 5577.5661 | F30: 7200 | G30: FALSE | I30: FALSE | J30: 10 | K30: =IF(G30,H30-E30,"") | L30: =MAX(0,E30-F30) -> 0 | M30: =IF(G30,0,J30) -> 10 | N30: =M30*L30 -> 0 | O30: =IF(P30,0,J30) -> 10 | P30: FALSE
A31: S003-WAT-03 | B31: Q2-0021 | C31: S003 | D31: 饮用水 | E31: ='Q2_逐箱交付'!D31 -> 5770.7033 | F31: 7200 | G31: FALSE | I31: FALSE | J31: 10 | K31: =IF(G31,H31-E31,"") | L31: =MAX(0,E31-F31) -> 0 | M31: =IF(G31,0,J31) -> 10 | N31: =M31*L31 -> 0 | O31: =IF(P31,0,J31) -> 10 | P31: FALSE
A32: S003-WAT-04 | B32: Q2-0019 | C32: S003 | D32: 饮用水 | E32: ='Q2_逐箱交付'!D32 -> 5577.5661 | F32: 7200 | G32: FALSE | I32: FALSE | J32: 10 | K32: =IF(G32,H32-E32,"") | L32: =MAX(0,E32-F32) -> 0 | M32: =IF(G32,0,J32) -> 10 | N32: =M32*L32 -> 0 | O32: =IF(P32,0,J32) -> 10 | P32: FALSE
A33: S004-FOD-01 | B33: Q2-0016 | C33: S004 | D33: 应急食品 | E33: ='Q2_逐箱交付'!D33 -> 4064.9351 | F33: 10800 | G33: FALSE | I33: FALSE | J33: 8 | K33: =IF(G33,H33-E33,"") | L33: =MAX(0,E33-F33) -> 0 | M33: =IF(G33,0,J33) -> 8 | N33: =M33*L33 -> 0 | O33: =IF(P33,0,J33) -> 8 | P33: FALSE
A34: S004-HYG-01 | B34: Q2-0016 | C34: S004 | D34: 生活卫生用品 | E34: ='Q2_逐箱交付'!D34 -> 4064.9351 | F34: 14400 | G34: FALSE | I34: FALSE | J34: 6 | K34: =IF(G34,H34-E34,"") | L34: =MAX(0,E34-F34) -> 0 | M34: =IF(G34,0,J34) -> 6 | N34: =M34*L34 -> 0 | O34: =IF(P34,0,J34) -> 6 | P34: FALSE
A35: S004-MED-01 | B35: Q2-0016 | C35: S004 | D35: 医疗物资 | E35: ='Q2_逐箱交付'!D35 -> 4064.9351 | F35: 7200 | G35: TRUE | H35: 7200 | I35: TRUE | J35: 20 | K35: =IF(G35,H35-E35,"") -> 3135.0649 | L35: =MAX(0,E35-F35) -> 0 | M35: =IF(G35,0,J35) -> 0 | N35: =M35*L35 -> 0 | O35: =IF(P35,0,J35) -> 0 | P35: TRUE
A36: S004-WAT-01 | B36: Q2-0016 | C36: S004 | D36: 饮用水 | E36: ='Q2_逐箱交付'!D36 -> 4064.9351 | F36: 7200 | G36: TRUE | H36: 7200 | I36: TRUE | J36: 10 | K36: =IF(G36,H36-E36,"") -> 3135.0649 | L36: =MAX(0,E36-F36) -> 0 | M36: =IF(G36,0,J36) -> 0 | N36: =M36*L36 -> 0 | O36: =IF(P36,0,J36) -> 10 | P36: FALSE
A37: S004-WAT-02 | B37: Q2-0016 | C37: S004 | D37: 饮用水 | E37: ='Q2_逐箱交付'!D37 -> 4064.9351 | F37: 7200 | G37: FALSE | I37: FALSE | J37: 10 | K37: =IF(G37,H37-E37,"") | L37: =MAX(0,E37-F37) -> 0 | M37: =IF(G37,0,J37) -> 10 | N37: =M37*L37 -> 0 | O37: =IF(P37,0,J37) -> 10 | P37: FALSE
A38: S004-WAT-03 | B38: Q2-0016 | C38: S004 | D38: 饮用水 | E38: ='Q2_逐箱交付'!D38 -> 4064.9351 | F38: 7200 | G38: FALSE | I38: FALSE | J38: 10 | K38: =IF(G38,H38-E38,"") | L38: =MAX(0,E38-F38) -> 0 | M38: =IF(G38,0,J38) -> 10 | N38: =M38*L38 -> 0 | O38: =IF(P38,0,J38) -> 10 | P38: FALSE
A39: S005-FOD-01 | B39: Q2-0023 | C39: S005 | D39: 应急食品 | E39: ='Q2_逐箱交付'!D39 -> 6168.055 | F39: 14400 | G39: FALSE | I39: FALSE | J39: 6 | K39: =IF(G39,H39-E39,"") | L39: =MAX(0,E39-F39) -> 0 | M39: =IF(G39,0,J39) -> 6 | N39: =M39*L39 -> 0 | O39: =IF(P39,0,J39) -> 6 | P39: FALSE
A40: S005-HYG-01 | B40: Q2-0023 | C40: S005 | D40: 生活卫生用品 | E40: ='Q2_逐箱交付'!D40 -> 6168.055 | F40: 18000 | G40: FALSE | I40: FALSE | J40: 4 | K40: =IF(G40,H40-E40,"") | L40: =MAX(0,E40-F40) -> 0 | M40: =IF(G40,0,J40) -> 4 | N40: =M40*L40 -> 0 | O40: =IF(P40,0,J40) -> 4 | P40: FALSE
...

Sheet 核验_资源事件
A1: 资源类型 | B1: 资源编号 | C1: 架次编号 | D1: 阶段 | E1: 开始s | F1: 结束s | G1: 时长s
A2: 无人机 | B2: U01 | C2: Q2-0002 | D2: 任务 | E2: ='Q2_运输架次'!E3 -> 0 | F2: ='Q2_运输架次'!G3 -> 1250.907 | G2: =F2-E2 -> 1250.907
A3: 无人机 | B3: U01 | C3: Q2-0010 | D3: 任务 | E3: ='Q2_运输架次'!E11 -> 1250.907 | F3: ='Q2_运输架次'!G11 -> 3241.3058 | G3: =F3-E3 -> 1990.3989
A4: 无人机 | B4: U02 | C4: Q2-0001 | D4: 任务 | E4: ='Q2_运输架次'!E2 -> 0 | F4: ='Q2_运输架次'!G2 -> 2215.8496 | G4: =F4-E4 -> 2215.8496
A5: 无人机 | B5: U02 | C5: Q2-0015 | D5: 任务 | E5: ='Q2_运输架次'!E16 -> 2215.8496 | F5: ='Q2_运输架次'!G16 -> 3529.3262 | G5: =F5-E5 -> 1313.4766
A6: 无人机 | B6: U02 | C6: Q2-0021 | D6: 任务 | E6: ='Q2_运输架次'!E22 -> 4421.3614 | F6: ='Q2_运输架次'!G22 -> 6624.0986 | G6: =F6-E6 -> 2202.7372
A7: 无人机 | B7: U03 | C7: Q2-0003 | D7: 任务 | E7: ='Q2_运输架次'!E4 -> 0 | F7: ='Q2_运输架次'!G4 -> 1313.4766 | G7: =F7-E7 -> 1313.4766
A8: 无人机 | B8: U03 | C8: Q2-0011 | D8: 任务 | E8: ='Q2_运输架次'!E12 -> 1313.4766 | F8: ='Q2_运输架次'!G12 -> 3761.0393 | G8: =F8-E8 -> 2447.5627
A9: 无人机 | B9: U03 | C9: Q2-0018 | D9: 任务 | E9: ='Q2_运输架次'!E19 -> 3761.0393 | F9: ='Q2_运输架次'!G19 -> 4983.0676 | G9: =F9-E9 -> 1222.0283
A10: 无人机 | B10: U03 | C10: Q2-0025 | D10: 任务 | E10: ='Q2_运输架次'!E26 -> 5059.6813 | F10: ='Q2_运输架次'!G26 -> 6313.158 | G10: =F10-E10 -> 1253.4766
A11: 无人机 | B11: U04 | C11: Q2-0007 | D11: 任务 | E11: ='Q2_运输架次'!E8 -> 0 | F11: ='Q2_运输架次'!G8 -> 1904.187 | G11: =F11-E11 -> 1904.187
A12: 无人机 | B12: U04 | C12: Q2-0014 | D12: 任务 | E12: ='Q2_运输架次'!E15 -> 2192.3725 | F12: ='Q2_运输架次'!G15 -> 3804.5354 | G12: =F12-E12 -> 1612.1628
A13: 无人机 | B13: U04 | C13: Q2-0024 | D13: 任务 | E13: ='Q2_运输架次'!E25 -> 4870.1988 | F13: ='Q2_运输架次'!G25 -> 6558.8384 | G13: =F13-E13 -> 1688.6396
A14: 无人机 | B14: U05 | C14: Q2-0005 | D14: 任务 | E14: ='Q2_运输架次'!E6 -> 0 | F14: ='Q2_运输架次'!G6 -> 1147.27 | G14: =F14-E14 -> 1147.27
A15: 无人机 | B15: U05 | C15: Q2-0009 | D15: 任务 | E15: ='Q2_运输架次'!E10 -> 1147.27 | F15: ='Q2_运输架次'!G10 -> 2702.6735 | G15: =F15-E15 -> 1555.4035
A16: 无人机 | B16: U05 | C16: Q2-0017 | D16: 任务 | E16: ='Q2_运输架次'!E18 -> 2702.6735 | F16: ='Q2_运输架次'!G18 -> 4604.5153 | G16: =F16-E16 -> 1901.8417
A17: 无人机 | B17: U05 | C17: Q2-0022 | D17: 任务 | E17: ='Q2_运输架次'!E23 -> 4604.5153 | F17: ='Q2_运输架次'!G23 -> 6446.357 | G17: =F17-E17 -> 1841.8417
A18: 无人机 | B18: U06 | C18: Q2-0004 | D18: 任务 | E18: ='Q2_运输架次'!E5 -> 0 | F18: ='Q2_运输架次'!G5 -> 1828.3276 | G18: =F18-E18 -> 1828.3276
A19: 无人机 | B19: U06 | C19: Q2-0013 | D19: 任务 | E19: ='Q2_运输架次'!E14 -> 1828.3276 | F19: ='Q2_运输架次'!G14 -> 3751.1544 | G19: =F19-E19 -> 1922.8268
A20: 无人机 | B20: U06 | C20: Q2-0020 | D20: 任务 | E20: ='Q2_运输架次'!E21 -> 4159.4193 | F20: ='Q2_运输架次'!G21 -> 6365.406 | G20: =F20-E20 -> 2205.9867
A21: 无人机 | B21: U07 | C21: Q2-0008 | D21: 任务 | E21: ='Q2_运输架次'!E9 -> 0 | F21: ='Q2_运输架次'!G9 -> 1692.175 | G21: =F21-E21 -> 1692.175
A22: 无人机 | B22: U07 | C22: Q2-0012 | D22: 任务 | E22: ='Q2_运输架次'!E13 -> 1692.175 | F22: ='Q2_运输架次'!G13 -> 3866.0172 | G22: =F22-E22 -> 2173.8422
A23: 无人机 | B23: U07 | C23: Q2-0019 | D23: 任务 | E23: ='Q2_运输架次'!E20 -> 3866.0172 | F23: ='Q2_运输架次'!G20 -> 6368.1949 | G23: =F23-E23 -> 2502.1777
A24: 无人机 | B24: U08 | C24: Q2-0006 | D24: 任务 | E24: ='Q2_运输架次'!E7 -> 0 | F24: ='Q2_运输架次'!G7 -> 2481.4378 | G24: =F24-E24 -> 2481.4378
A25: 无人机 | B25: U08 | C25: Q2-0016 | D25: 任务 | E25: ='Q2_运输架次'!E17 -> 2481.4378 | F25: ='Q2_运输架次'!G17 -> 4782.4925 | G25: =F25-E25 -> 2301.0547
A26: 无人机 | B26: U08 | C26: Q2-0023 | D26: 任务 | E26: ='Q2_运输架次'!E24 -> 4794.8256 | F26: ='Q2_运输架次'!G24 -> 6672.0143 | G26: =F26-E26 -> 1877.1887
A27: 电池 | B27: A-BAT-01 | C27: Q2-0007 | D27: 任务 | E27: ='Q2_运输架次'!E8 -> 0 | F27: ='Q2_运输架次'!G8 -> 1904.187 | G27: =F27-E27 -> 1904.187
A28: 电池 | B28: A-BAT-01 | C28: Q2-0007 | D28: 充电 | E28: ='Q2_运输架次'!G8 -> 1904.187 | F28: ='核验_架次详情'!H8 -> 3037.8365 | G28: =F28-E28 -> 1133.6494
A29: 电池 | B29: A-BAT-02 | C29: Q2-0010 | D29: 任务 | E29: ='Q2_运输架次'!E11 -> 1250.907 | F29: ='Q2_运输架次'!G11 -> 3241.3058 | G29: =F29-E29 -> 1990.3989
A30: 电池 | B30: A-BAT-02 | C30: Q2-0010 | D30: 充电 | E30: ='Q2_运输架次'!G11 -> 3241.3058 | F30: ='核验_架次详情'!H11 -> 4425.8067 | G30: =F30-E30 -> 1184.5009
A31: 电池 | B31: A-BAT-03 | C31: Q2-0002 | D31: 任务 | E31: ='Q2_运输架次'!E3 -> 0 | F31: ='Q2_运输架次'!G3 -> 1250.907 | G31: =F31-E31 -> 1250.907
A32: 电池 | B32: A-BAT-03 | C32: Q2-0002 | D32: 充电 | E32: ='Q2_运输架次'!G3 -> 1250.907 | F32: ='核验_架次详情'!H3 -> 2121.3676 | G32: =F32-E32 -> 870.46064
A33: 电池 | B33: A-BAT-03 | C33: Q2-0015 | D33: 任务 | E33: ='Q2_运输架次'!E16 -> 2215.8496 | F33: ='Q2_运输架次'!G16 -> 3529.3262 | G33: =F33-E33 -> 1313.4766
A34: 电池 | B34: A-BAT-03 | C34: Q2-0015 | D34: 充电 | E34: ='Q2_运输架次'!G16 -> 3529.3262 | F34: ='核验_架次详情'!H16 -> 4421.3614 | G34: =F34-E34 -> 892.03512
A35: 电池 | B35: A-BAT-03 | C35: Q2-0021 | D35: 任务 | E35: ='Q2_运输架次'!E22 -> 4421.3614 | F35: ='Q2_运输架次'!G22 -> 6624.0986 | G35: =F35-E35 -> 2202.7372
A36: 电池 | B36: A-BAT-03 | C36: Q2-0021 | D36: 充电 | E36: ='Q2_运输架次'!G22 -> 6624.0986 | F36: ='核验_架次详情'!H22 -> 7971.0504 | G36: =F36-E36 -> 1346.9518
A37: 电池 | B37: A-BAT-04 | C37: Q2-0001 | D37: 任务 | E37: ='Q2_运输架次'!E2 -> 0 | F37: ='Q2_运输架次'!G2 -> 2215.8496 | G37: =F37-E37 -> 2215.8496
A38: 电池 | B38: A-BAT-04 | C38: Q2-0001 | D38: 充电 | E38: ='Q2_运输架次'!G2 -> 2215.8496 | F38: ='核验_架次详情'!H2 -> 3586.9993 | G38: =F38-E38 -> 1371.1497
A39: 电池 | B39: A-BAT-04 | C39: Q2-0018 | D39: 任务 | E39: ='Q2_运输架次'!E19 -> 3761.0393 | F39: ='Q2_运输架次'!G19 -> 4983.0676 | G39: =F39-E39 -> 1222.0283
A40: 电池 | B40: A-BAT-04 | C40: Q2-0018 | D40: 充电 | E40: ='Q2_运输架次'!G19 -> 4983.0676 | F40: ='核验_架次详情'!H19 -> 5815.8762 | G40: =F40-E40 -> 832.80861
...

Sheet 核验_资源汇总
A1: 资源类型 | B1: 资源编号 | C1: 机型编号 | D1: 使用次数 | E1: 任务总时长s | F1: 充电总时长s | G1: 最后返场s | H1: 最后充满s | I1: 无人机占用率
A2: 实体运输无人机 | B2: U01 | C2: A | D2: =COUNTA('Q2_运输架次'!A3,'Q2_运输架次'!A11) -> 2 | E2: =SUM('核验_架次详情'!I3,'核验_架次详情'!I11) -> 3241.3058 | G2: =MAX('Q2_运输架次'!G3,'Q2_运输架次'!G11) -> 3241.3058 | I2: =E2/'指标汇总'!B4 -> 0.48580619
A3: 实体运输无人机 | B3: U02 | C3: A | D3: =COUNTA('Q2_运输架次'!A2,'Q2_运输架次'!A16,'Q2_运输架次'!A22) -> 3 | E3: =SUM('核验_架次详情'!I2,'核验_架次详情'!I16,'核验_架次详情'!I22) -> 5732.0635 | G3: =MAX('Q2_运输架次'!G2,'Q2_运输架次'!G16,'Q2_运输架次'!G22) -> 6624.0986 | I3: =E3/'指标汇总'!B4 -> 0.85912038
A4: 实体运输无人机 | B4: U03 | C4: A | D4: =COUNTA('Q2_运输架次'!A4,'Q2_运输架次'!A12,'Q2_运输架次'!A19,'Q2_运输架次'!A26) -> 4 | E4: =SUM('核验_架次详情'!I4,'核验_架次详情'!I12,'核验_架次详情'!I19,'核验_架次详情'!I26) -> 6236.5442 | G4: =MAX('Q2_运输架次'!G4,'Q2_运输架次'!G12,'Q2_运输架次'!G19,'Q2_运输架次'!G26) -> 6313.158 | I4: =E4/'指标汇总'!B4 -> 0.93473184
A5: 实体运输无人机 | B5: U04 | C5: A | D5: =COUNTA('Q2_运输架次'!A8,'Q2_运输架次'!A15,'Q2_运输架次'!A25) -> 3 | E5: =SUM('核验_架次详情'!I8,'核验_架次详情'!I15,'核验_架次详情'!I25) -> 5204.9895 | G5: =MAX('Q2_运输架次'!G8,'Q2_运输架次'!G15,'Q2_运输架次'!G25) -> 6558.8384 | I5: =E5/'指标汇总'!B4 -> 0.78012265
A6: 实体运输无人机 | B6: U05 | C6: B | D6: =COUNTA('Q2_运输架次'!A6,'Q2_运输架次'!A10,'Q2_运输架次'!A18,'Q2_运输架次'!A23) -> 4 | E6: =SUM('核验_架次详情'!I6,'核验_架次详情'!I10,'核验_架次详情'!I18,'核验_架次详情'!I23) -> 6446.357 | G6: =MAX('Q2_运输架次'!G6,'Q2_运输架次'!G10,'Q2_运输架次'!G18,'Q2_运输架次'!G23) -> 6446.357 | I6: =E6/'指标汇总'!B4 -> 0.96617853
A7: 实体运输无人机 | B7: U06 | C7: B | D7: =COUNTA('Q2_运输架次'!A5,'Q2_运输架次'!A14,'Q2_运输架次'!A21) -> 3 | E7: =SUM('核验_架次详情'!I5,'核验_架次详情'!I14,'核验_架次详情'!I21) -> 5957.1411 | G7: =MAX('Q2_运输架次'!G5,'Q2_运输架次'!G14,'Q2_运输架次'!G21) -> 6365.406 | I7: =E7/'指标汇总'!B4 -> 0.89285496
A8: 实体运输无人机 | B8: U07 | C8: C | D8: =COUNTA('Q2_运输架次'!A9,'Q2_运输架次'!A13,'Q2_运输架次'!A20) -> 3 | E8: =SUM('核验_架次详情'!I9,'核验_架次详情'!I13,'核验_架次详情'!I20) -> 6368.1949 | G8: =MAX('Q2_运输架次'!G9,'Q2_运输架次'!G13,'Q2_运输架次'!G20) -> 6368.1949 | I8: =E8/'指标汇总'!B4 -> 0.95446362
A9: 实体运输无人机 | B9: U08 | C9: C | D9: =COUNTA('Q2_运输架次'!A7,'Q2_运输架次'!A17,'Q2_运输架次'!A24) -> 3 | E9: =SUM('核验_架次详情'!I7,'核验_架次详情'!I17,'核验_架次详情'!I24) -> 6659.6812 | G9: =MAX('Q2_运输架次'!G7,'Q2_运输架次'!G17,'Q2_运输架次'!G24) -> 6672.0143 | I9: =E9/'指标汇总'!B4 -> 0.99815151
A10: 共享电池 | B10: A-BAT-01 | C10: A | D10: =COUNTA('Q2_运输架次'!A8) -> 1 | E10: =SUM('核验_架次详情'!I8) -> 1904.187 | F10: =SUM('核验_架次详情'!J8) -> 1133.6494 | G10: =MAX('Q2_运输架次'!G8) -> 1904.187 | H10: =MAX('核验_架次详情'!H8) -> 3037.8365
A11: 共享电池 | B11: A-BAT-02 | C11: A | D11: =COUNTA('Q2_运输架次'!A11) -> 1 | E11: =SUM('核验_架次详情'!I11) -> 1990.3989 | F11: =SUM('核验_架次详情'!J11) -> 1184.5009 | G11: =MAX('Q2_运输架次'!G11) -> 3241.3058 | H11: =MAX('核验_架次详情'!H11) -> 4425.8067
A12: 共享电池 | B12: A-BAT-03 | C12: A | D12: =COUNTA('Q2_运输架次'!A3,'Q2_运输架次'!A16,'Q2_运输架次'!A22) -> 3 | E12: =SUM('核验_架次详情'!I3,'核验_架次详情'!I16,'核验_架次详情'!I22) -> 4767.1208 | F12: =SUM('核验_架次详情'!J3,'核验_架次详情'!J16,'核验_架次详情'!J22) -> 3109.4476 | G12: =MAX('Q2_运输架次'!G3,'Q2_运输架次'!G16,'Q2_运输架次'!G22) -> 6624.0986 | H12: =MAX('核验_架次详情'!H3,'核验_架次详情'!H16,'核验_架次详情'!H22) -> 7971.0504
A13: 共享电池 | B13: A-BAT-04 | C13: A | D13: =COUNTA('Q2_运输架次'!A2,'Q2_运输架次'!A19) -> 2 | E13: =SUM('核验_架次详情'!I2,'核验_架次详情'!I19) -> 3437.8779 | F13: =SUM('核验_架次详情'!J2,'核验_架次详情'!J19) -> 2203.9583 | G13: =MAX('Q2_运输架次'!G2,'Q2_运输架次'!G19) -> 4983.0676 | H13: =MAX('核验_架次详情'!H2,'核验_架次详情'!H19) -> 5815.8762
A14: 共享电池 | B14: A-BAT-05 | C14: A | D14: =COUNTA('Q2_运输架次'!A4,'Q2_运输架次'!A15,'Q2_运输架次'!A25) -> 3 | E14: =SUM('核验_架次详情'!I4,'核验_架次详情'!I15,'核验_架次详情'!I25) -> 4614.2791 | F14: =SUM('核验_架次详情'!J4,'核验_架次详情'!J15,'核验_架次详情'!J25) -> 3095.9701 | G14: =MAX('Q2_运输架次'!G4,'Q2_运输架次'!G15,'Q2_运输架次'!G25) -> 6558.8384 | H14: =MAX('核验_架次详情'!H4,'核验_架次详情'!H15,'核验_架次详情'!H25) -> 7710.2492
A15: 共享电池 | B15: A-BAT-06 | C15: A | D15: =COUNTA('Q2_运输架次'!A12,'Q2_运输架次'!A26) -> 2 | E15: =SUM('核验_架次详情'!I12,'核验_架次详情'!I26) -> 3701.0393 | F15: =SUM('核验_架次详情'!J12,'核验_架次详情'!J26) -> 2157.7325 | G15: =MAX('Q2_运输架次'!G12,'Q2_运输架次'!G26) -> 6313.158 | H15: =MAX('核验_架次详情'!H12,'核验_架次详情'!H26) -> 7172.2484
A16: 共享电池 | B16: B-BAT-01 | C16: B | D16: =COUNTA('Q2_运输架次'!A5,'Q2_运输架次'!A23) -> 2 | E16: =SUM('核验_架次详情'!I5,'核验_架次详情'!I23) -> 3670.1693 | F16: =SUM('核验_架次详情'!J5,'核验_架次详情'!J23) -> 3455.3486 | G16: =MAX('Q2_运输架次'!G5,'Q2_运输架次'!G23) -> 6446.357 | H16: =MAX('核验_架次详情'!H5,'核验_架次详情'!H23) -> 8235.084
A17: 共享电池 | B17: B-BAT-02 | C17: B | D17: =COUNTA('Q2_运输架次'!A14) -> 1 | E17: =SUM('核验_架次详情'!I14) -> 1922.8268 | F17: =SUM('核验_架次详情'!J14) -> 1859.4792 | G17: =MAX('Q2_运输架次'!G14) -> 3751.1544 | H17: =MAX('核验_架次详情'!H14) -> 5610.6336
A18: 共享电池 | B18: B-BAT-03 | C18: B | D18: =COUNTA('Q2_运输架次'!A6,'Q2_运输架次'!A18) -> 2 | E18: =SUM('核验_架次详情'!I6,'核验_架次详情'!I18) -> 3049.1118 | F18: =SUM('核验_架次详情'!J6,'核验_架次详情'!J18) -> 2992.8862 | G18: =MAX('Q2_运输架次'!G6,'Q2_运输架次'!G18) -> 4604.5153 | H18: =MAX('核验_架次详情'!H6,'核验_架次详情'!H18) -> 6468.6842
A19: 共享电池 | B19: B-BAT-04 | C19: B | D19: =COUNTA('Q2_运输架次'!A10,'Q2_运输架次'!A21) -> 2 | E19: =SUM('核验_架次详情'!I10,'核验_架次详情'!I21) -> 3761.3902 | F19: =SUM('核验_架次详情'!J10,'核验_架次详情'!J21) -> 3345.3059 | G19: =MAX('Q2_运输架次'!G10,'Q2_运输架次'!G21) -> 6365.406 | H19: =MAX('核验_架次详情'!H10,'核验_架次详情'!H21) -> 8253.9662
A20: 共享电池 | B20: C-BAT-01 | C20: C | D20: =COUNTA('Q2_运输架次'!A7,'Q2_运输架次'!A24) -> 2 | E20: =SUM('核验_架次详情'!I7,'核验_架次详情'!I24) -> 4358.6265 | F20: =SUM('核验_架次详情'!J7,'核验_架次详情'!J24) -> 4290.2289 | G20: =MAX('Q2_运输架次'!G7,'Q2_运输架次'!G24) -> 6672.0143 | H20: =MAX('核验_架次详情'!H7,'核验_架次详情'!H24) -> 8648.8554
A21: 共享电池 | B21: C-BAT-02 | C21: C | D21: =COUNTA('Q2_运输架次'!A17) -> 1 | E21: =SUM('核验_架次详情'!I17) -> 2301.0547 | F21: =SUM('核验_架次详情'!J17) -> 2499.7493 | G21: =MAX('Q2_运输架次'!G17) -> 4782.4925 | H21: =MAX('核验_架次详情'!H17) -> 7282.2418
A22: 共享电池 | B22: C-BAT-03 | C22: C | D22: =COUNTA('Q2_运输架次'!A9,'Q2_运输架次'!A20) -> 2 | E22: =SUM('核验_架次详情'!I9,'核验_架次详情'!I20) -> 4194.3528 | F22: =SUM('核验_架次详情'!J9,'核验_架次详情'!J20) -> 4169.7679 | G22: =MAX('Q2_运输架次'!G9,'Q2_运输架次'!G20) -> 6368.1949 | H22: =MAX('核验_架次详情'!H9,'核验_架次详情'!H20) -> 8914.4398
A23: 共享电池 | B23: C-BAT-04 | C23: C | D23: =COUNTA('Q2_运输架次'!A13) -> 1 | E23: =SUM('核验_架次详情'!I13) -> 2173.8422 | F23: =SUM('核验_架次详情'!J13) -> 2534.4403 | G23: =MAX('Q2_运输架次'!G13) -> 3866.0172 | H23: =MAX('核验_架次详情'!H13) -> 6400.4575

Sheet 联合非支配档案
A1: 方案编号 | B1: 最终提交标记 | C1: 架次数N | D1: 能耗kWh | E1: 最晚返场s | F1: 加权迟到s | G1: 软箱迟到箱数 | H1: 遗憾下界 | I1: 遗憾上界 | J1: 方案来源
A2: PF0001 | B2: TRUE | C2: 25 | D2: 71.319092 | E2: 6672.0143 | F2: 0 | G2: 0 | H2: 0.058596416 | I2: 0.39596236 | J2: terminal_of_all_resources_polish_of_terminal_of_expanded_worker_4_step_56
A3: PF0002 | B3: FALSE | C3: 23 | D3: 68.149916 | E3: 7066.6279 | F3: 0 | G3: 0 | H3: 0.05701865 | I3: 0.43494709 | J3: terminal_of_all_resources_polish_of_direct_expanded_equal_preference
A4: PF0003 | B4: FALSE | C4: 22 | D4: 67.359986 | E4: 7831.1247 | F4: 51.214492 | G4: 2 | H4: 0.26266913 | I4: 0.64059757 | J4: terminal_of_all_resources_polish_of_expanded_worker_3_step_56
A5: PF0004 | B5: FALSE | C5: 23 | D5: 66.297413 | E5: 7881.6462 | F5: 37.647775 | G5: 2 | H5: 0.27216215 | I5: 0.64297551 | J5: terminal_of_all_resources_polish_of_terminal_of_expanded_worker_0_step_67
A6: PF0005 | B6: FALSE | C6: 21 | D6: 67.32236 | E6: 8013.6462 | F6: 0 | G6: 0 | H6: 0.2735182 | I6: 0.65144663 | J6: terminal_of_all_resources_polish_of_terminal_of_initializer_seed_20260975_mode_3
A7: PF0006 | B7: FALSE | C7: 22 | D7: 64.392269 | E7: 8337.1404 | F7: 42.238392 | G7: 2 | H7: 0.36526268 | I7: 0.73578901 | J7: terminal_of_all_resources_polish_of_expanded_worker_2_step_19
A8: PF0007 | B8: FALSE | C8: 22 | D8: 64.565605 | E8: 8427.0719 | F8: 0 | G8: 0 | H8: 0.36542798 | I8: 0.73689026 | J8: terminal_of_all_resources_polish_of_expanded_worker_2_step_13
A9: PF0008 | B9: FALSE | C9: 23 | D9: 63.260212 | E9: 9069.5672 | F9: 109.8014 | G9: 3 | H9: 0.59814389 | I9: 0.96833481 | J9: terminal_of_ALNS_comparison
A10: PF0009 | B10: FALSE | C10: 21 | D10: 62.720525 | E10: 9584.2986 | F10: 203.27679 | G10: 4 | H10: 0.74271753 | I10: 1.1142171 | J10: terminal_of_all_resources_polish_of_terminal_of_expanded_worker_7_step_49
A11: PF0010 | B11: FALSE | C11: 20 | D11: 60.917526 | E11: 9163.5489 | F11: 446.6242 | G11: 5 | H11: 0.74659989 | I11: 1.118364 | J11: terminal_of_all_resources_polish_of_expanded_worker_0_step_24
A12: PF0011 | B12: FALSE | C12: 20 | D12: 60.704972 | E12: 9163.5489 | F12: 520.79981 | G12: 6 | H12: 0.78621048 | I12: 1.1568269 | J12: terminal_of_fixed_original_resources_lateness_repair

Sheet 求解说明
A1: 项目 | B1: 内容
A2: 本次结果定位 | B2: 仅O01换电的可行基准；不代表允许服务区途中换电的完整专家规则下的全局结果。
A3: 专家补充（用户原话记录） | B3: 不能携带备用电池；可在有电池地方更换不限O01；初始共享电池都在O01。
A4: 基准能源安排 | B4: 本方案每架次绑定一块电池，全程不携带备用电池，换电均在O01；服务区初始电池库存为0。
A5: 尚待明确的专家规则 | B5: 服务区能否充电、途中换电是否必须满电尚待确认；本导出不设服务区充电能力或额外库存。
A6: 最终方案来源 | B6: terminal_of_all_resources_polish_of_terminal_of_expanded_worker_4_step_56
A7: 最终方案文件 | B7: D:\研究生\比赛\数学建模\2026\问题二\改进搜索_20260924\最终方案.json
A8: 最终方案SHA256 | B8: 1939cce13167720a7e36a7a9fff3f3032b89486fda4124d3dafc733fb09f6b26
A9: 非支配档案文件 | B9: D:\研究生\比赛\数学建模\2026\问题二\改进搜索_20260924\联合非支配档案.json
A10: 档案SHA256 | B10: deadacd5b16073630b7ba78329be0b4748ccb34568b7aa4a0502f0263b68490b
A11: 格式参考 | B11: D:\研究生\比赛\数学建模\2026\问题二\问题二_结果提交.xlsx
A12: 参考工作簿SHA256 | B12: 709d3b6f99a0d4cfb61de01bc7c1ea77f168e96d1f905891fff65643093faa23
... A16: 仅O01换电基准的搜索范围 | B16: Expanded finite-library heuristic search with certified relaxation lower bounds; no full-route optimum claim
A17: 初始候选库数 | B17: 26192
A18: 最终评价候选库数 | B18: 28216
A19: 最终候选系数SHA256 | B19: 96c73b04ebaeb105368e4298d3bd871ceab92c6734e580a835a9988780dc4058
A20: 候选库是否完整 | B20: FALSE
A21: 物理模型 | B21: Same audited q2_data physical assumptions; no parameter tuning against external answers
A22: 软迟到定义 | B22: 软箱为既非医疗也非首批；逐箱L列为正迟到，M列为软箱权，N列为两者乘积。
A23: 资源占用 | B23: 无人机任务区间[准备开始,返场]；电池任务同区间，返场后充至满电才可复用。资源事件包括最后一次任务后的充电。
A24: 时间单位 | B24: 所有任务时刻、持续时间、充电时间与迟到值均为秒；开始时刻指开始准备。
A25: 返航SOC | B25: 核验_架次详情G列为0–1数值，以百分比格式显示。
A26: 遗憾解释 | B26: 来自输入JSON中共同档案/候选范围的上下界；导出不重新证明稳健最优性，不与异库界无条件比较。
A27: 公式缓存 | B27: Excel公式保留，Python有限公式解释器从工作簿单元格重算缓存；Excel打开时自动重算。
A28: 独立核验是否匹配本方案 | B28: TRUE
A29: 匹配核验记录all | B29: TRUE
A30: 导出核验边界 | B30: 检查输入一致性、覆盖去重、资源重叠、硬时限、公式与typed数值；不替代DEM/物理模型独立审查。
